Workbook

Sheet List1
A1: ITEM | B1: QTY | C1: CALL OFF | D1: MOLD DESIGNATION | E1: MOLD WILL BE DONE | F1: PRODUCTION (WEEK)
A2: SL-300 BP 01 | B2: 3 | C2: 1 | D2: =VLOOKUP(A2,List2!$B$2:$C$115,2,0) -> NHK 10 | E2: 46247 | F2: 37
A3: SL-300 BP 02 | B3: 6 | C3: 1 | D3: =VLOOKUP(A3,List2!$B$2:$C$115,2,0) -> NHK3 | E3: 46262 | F3: 37 + 38
A4: SL-300 BP 03 | B4: 1 | C4: 1 | D4: =VLOOKUP(A4,List2!$B$2:$C$115,2,0) -> NHK3 | E4: 46262 | F4: 38
A5: SL-300 BP 04 | B5: 1 | C5: 1 | D5: =VLOOKUP(A5,List2!$B$2:$C$115,2,0) -> NHK1 | E5: 46254 | F5: 41
A6: SL-300 BP 08 | B6: 1 | C6: 1 | D6: =VLOOKUP(A6,List2!$B$2:$C$115,2,0) -> NHK1 | E6: 46254 | F6: 41
A7: SL-300 BP 09 | B7: 2 | C7: 1 | D7: =VLOOKUP(A7,List2!$B$2:$C$115,2,0) -> NHK1 | E7: 46254 | F7: 41
A8: SL-300 BP 10 | B8: 1 | C8: 1 | D8: =VLOOKUP(A8,List2!$B$2:$C$115,2,0) -> NHK1 | E8: 46254 | F8: 41
A9: SL-300 BP 13 | B9: 2 | C9: 1 | D9: =VLOOKUP(A9,List2!$B$2:$C$115,2,0) -> NHK3 | E9: 46262 | F9: 38 + 39
A10: SL-300 DR 01 | B10: 3 | C10: 1 | D10: =VLOOKUP(A10,List2!$B$2:$C$115,2,0) -> NHK2 | E10: 46254 | F10: 42
A11: SL-300 DR 02 | B11: 1 | C11: 1 | D11: =VLOOKUP(A11,List2!$B$2:$C$115,2,0) -> NHK2 | E11: 46254 | F11: 43
A12: SL-300 DR 03 | B12: 1 | C12: 1 | D12: =VLOOKUP(A12,List2!$B$2:$C$115,2,0) -> NHK2 | E12: 46254 | F12: 43
A13: SL-300 DR 04 | B13: 1 | C13: 1 | D13: =VLOOKUP(A13,List2!$B$2:$C$115,2,0) -> NHK2 | E13: 46254 | F13: 43
A14: SL-300 DR 12 | B14: 1 | C14: 1 | D14: =VLOOKUP(A14,List2!$B$2:$C$115,2,0) -> NHK 8 | E14: 46261 | F14: 43
A15: SL-300 DR FP 20 | B15: 3 | C15: 1 | D15: =VLOOKUP(A15,List2!$B$2:$C$115,2,0) -> NHK7 | E15: READY TO SPRAY | F15: 35
A16: SL-300 DR FP 21 | B16: 1 | C16: 1 | D16: =VLOOKUP(A16,List2!$B$2:$C$115,2,0) -> NHK7 | E16: READY TO SPRAY | F16: 35
A17: SL-300 DR FP 22 | B17: 1 | C17: 1 | D17: =VLOOKUP(A17,List2!$B$2:$C$115,2,0) -> NHK7 | E17: READY TO SPRAY | F17: 35
A18: SL-300 DR FP 23 | B18: 1 | C18: 1 | D18: =VLOOKUP(A18,List2!$B$2:$C$115,2,0) -> NHK7 | E18: READY TO SPRAY | F18: 36
A19: SL-300 DR FP 28 | B19: 1 | C19: 1 | D19: =VLOOKUP(A19,List2!$B$2:$C$115,2,0) -> NHK 9 | E19: 46266 | F19: 43
A20: SL-300 EP 01 | B20: 1 | C20: 1 | D20: =VLOOKUP(A20,List2!$B$2:$C$115,2,0) -> NHK5 | E20: READY TO SPRAY | F20: 35
A21: SL-300 EP 02 | B21: 1 | C21: 1 | D21: =VLOOKUP(A21,List2!$B$2:$C$115,2,0) -> NHK5 | E21: READY TO SPRAY | F21: 35
A22: SL-300 EP 03 | B22: 1 | C22: 1 | D22: =VLOOKUP(A22,List2!$B$2:$C$115,2,0) -> NHK5 | E22: READY TO SPRAY | F22: 35
A23: SL-300 EP 04 | B23: 2 | C23: 1 | D23: =VLOOKUP(A23,List2!$B$2:$C$115,2,0) -> NHK5 | E23: READY TO SPRAY | F23: 35
A24: SL-300 FP 10 | B24: 1 | C24: 1 | D24: =VLOOKUP(A24,List2!$B$2:$C$115,2,0) -> NHK7 | E24: READY TO SPRAY | F24: 36
A25: SL-300 FP 11 | B25: 2 | C25: 1 | D25: =VLOOKUP(A25,List2!$B$2:$C$115,2,0) -> NHK6 | E25: READY TO SPRAY | F25: 35
A26: SL-300 FP 12 | B26: 1 | C26: 1 | D26: =VLOOKUP(A26,List2!$B$2:$C$115,2,0) -> NHK6 | E26: READY TO SPRAY | F26: 35
A27: SL-300 FP 13 | B27: 1 | C27: 1 | D27: =VLOOKUP(A27,List2!$B$2:$C$115,2,0) -> NHK6 | E27: READY TO SPRAY | F27: 35
A28: SL-300 FP 14 | B28: 1 | C28: 1 | D28: =VLOOKUP(A28,List2!$B$2:$C$115,2,0) -> NHK7 | E28: READY TO SPRAY | F28: 36
A29: SL-300 FP 15 | B29: 3 | C29: 1 | D29: =VLOOKUP(A29,List2!$B$2:$C$115,2,0) -> NHK6 | E29: READY TO SPRAY | F29: 35 + 36
A30: SL-300 FP 16 | B30: 1 | C30: 1 | D30: =VLOOKUP(A30,List2!$B$2:$C$115,2,0) -> NHK6 | E30: READY TO SPRAY | F30: 36
A31: SL-300 FP 17 | B31: 1 | C31: 1 | D31: =VLOOKUP(A31,List2!$B$2:$C$115,2,0) -> NHK7 | E31: READY TO SPRAY | F31: 36
A32: SL-300 FP 18 | B32: 3 | C32: 1 | D32: =VLOOKUP(A32,List2!$B$2:$C$115,2,0) -> NHK6 | E32: READY TO SPRAY | F32: 36 + 37
A33: SL-300 FP 19 | B33: 1 | C33: 1 | D33: =VLOOKUP(A33,List2!$B$2:$C$115,2,0) -> NHK6 | E33: READY TO SPRAY | F33: 37
A34: SL-300 FP 20 | B34: 1 | C34: 1 | D34: =VLOOKUP(A34,List2!$B$2:$C$115,2,0) -> NHK7 | E34: READY TO SPRAY | F34: 36
A35: SL-300 FP 21 | B35: 3 | C35: 1 | D35: =VLOOKUP(A35,List2!$B$2:$C$115,2,0) -> NHK6 | E35: READY TO SPRAY | F35: 37
A36: SL-300 FP 22 | B36: 1 | C36: 1 | D36: =VLOOKUP(A36,List2!$B$2:$C$115,2,0) -> NHK6 | E36: READY TO SPRAY | F36: 38
A37: SL-300 FP 23 | B37: 1 | C37: 1 | D37: =VLOOKUP(A37,List2!$B$2:$C$115,2,0) -> NHK7 | E37: READY TO SPRAY | F37: 37
A38: SL-300 FP 24 | B38: 3 | C38: 1 | D38: =VLOOKUP(A38,List2!$B$2:$C$115,2,0) -> NHK6 | E38: READY TO SPRAY | F38: 38
A39: SL-300 FP 25 | B39: 1 | C39: 1 | D39: =VLOOKUP(A39,List2!$B$2:$C$115,2,0) -> NHK6 | E39: READY TO SPRAY | F39: 38
A40: SL-300 FP AD 01 | B40: 6 | C40: 1 | D40: =VLOOKUP(A40,List2!$B$2:$C$115,2,0) -> NHK4 | E40: READY TO SPRAY | F40: 35 + 36
...

Sheet List2
B2: SL-300 BP 08 | C2: NHK1
B3: SL-300 BP 10 | C3: NHK1
B4: SL-300 BP 09 | C4: NHK1
B5: SL-300 BP 11 | C5: NHK1
B6: SL-300 BP 05 | C6: NHK1
B7: SL-300 BP 04 | C7: NHK1
B8: SL-300
B9: SL-300 DR 07 | C9: NHK2
B10: SL-300 DR 05 | C10: NHK2
B11: SL-300 DR 06 | C11: NHK2
B12: SL-300 DR 08 | C12: NHK2
B13: SL-300 DR 04 | C13: NHK2
B14: SL-300 DR 09 | C14: NHK2
B15: SL-300 DR 03 | C15: NHK2
B16: SL-300 DR 01 | C16: NHK2
B17: SL-300 DR 10 | C17: NHK2
B18: SL-300 DR 02 | C18: NHK2
B19: SL-300 DR 11 | C19: NHK2
B20: SL-300
B21: SL-300 BP 07 | C21: NHK3
B22: SL-300 BP 12 | C22: NHK3
B23: SL-300 BP 03 | C23: NHK3
B24: SL-300 BP 13 | C24: NHK3
B25: SL-300 BP 02 | C25: NHK3
B26: SL-300 BP 06 | C26: NHK3
B27: SL-300
B28: SL-300
B29: SL-300
B30: SL-300 FP AD 01 | C30: NHK4
B31: SL-300 FP AD 02 | C31: NHK4
B32: SL-300 FP AD 04 | C32: NHK4
B33: SL-300 FP AD 03 | C33: NHK4
B34: SL-300 FP AD 65 | C34: NHK4
B35: SL-300 FP AD 67 | C35: NHK4
B36: SL-300 FP AD 66 | C36: NHK4
B37: SL-300 LP 01 | C37: NHK4
B38: SL-300 LP 03 | C38: NHK4
B39: SL-300 LP 07 | C39: NHK4
B40: SL-300 LP 05 | C40: NHK4
B41: SL-300
...
